Workbook

Sheet January
B2: 1 | C2: Statistics Item | D2: Total | F2: North Region | K2: South Region | N2: Market Surveillance | Q2: Border Control | T2: Operations + Admin
C3: Total Cases and/or Complaints (Internal & External) received and closed | D3: Opened | E3: Closed | G3: Opened - Malta | H3: Opened - Gozo | I3: Closed - Malta | J3: Closed - Gozo | L3: Opened | M3: Closed | O3: Opened | P3: Closed | R3: Opened | S3: Closed | U3: Opened | V3: Closed
D4: =SUM(G4,H4,L4,O4,R4,U4) -> 0 | E4: =SUM(I4,J4,M4,P4,S4,V4) -> 0 | G4: =SUM(G5:G34) -> 0 | H4: =SUM(H5:H34) -> 0 | I4: =SUM(I5:I34) -> 0 | J4: =SUM(J5:J34) -> 0 | L4: =SUM(L5:L34) -> 0 | M4: =SUM(M5:M34) -> 0 | O4: =SUM(O5:O10) -> 0 | P4: =SUM(P5:P10) -> 0 | R4: =SUM(R5:R11) -> 0 | S4: =SUM(S5:S11) -> 0 | U4: =SUM(U5:U13) -> 0 | V4: =SUM(V5:V13) -> 0
F5: Waste Management Facilities | G5: 0 | H5: 0 | I5: 0 | J5: 0 | K5: Waste Management Facilities | L5: 0 | M5: 0 | N5: Local Waste Transfers – Waste Carriers | O5: 0 | P5: 0 | Q5: Wildlife trade / Species Protection & Control border movements | R5: 0 | S5: 0 | T5: Development / Development permit related | U5: 0 | V5: 0
F6: Quarries and related Industries | G6: 0 | H6: 0 | I6: 0 | J6: 0 | K6: Quarries and related Industries | L6: 0 | M6: 0 | N6: Shipments of waste | O6: 0 | P6: 0 | Q6: Wildlife Trade / Species Protection & Control excluding border movements | R6: 0 | S6: 0 | T6: AERs - Annual Environment Reports | U6: 0 | V6: 0
F7: Manufacturing operations | G7: 0 | H7: 0 | I7: 0 | J7: 0 | K7: Manufacturing operations | L7: 0 | M7: 0 | N7: Recycling points | O7: 0 | P7: 0 | Q7: GMOs - Genetically Modified Organisms | R7: 0 | S7: 0 | T7: Litter | U7: 0 | V7: 0
F8: Pharmaceutical industry | G8: 0 | H8: 0 | I8: 0 | J8: 0 | K8: Pharmaceutical industry | L8: 0 | M8: 0 | N8: Extended Producer Responsibility | O8: 0 | P8: 0 | Q8: FLEGT - Forest Law Enforcement, Governance and Trade | R8: 0 | S8: 0 | T8: Development Permit Clearances | U8: 0 | V8: 0
F9: Petrol Stations | G9: 0 | H9: 0 | I9: 0 | J9: 0 | K9: Petrol Stations | L9: 0 | M9: 0 | N9: Consignment notes | O9: 0 | P9: 0 | Q9: EUTR/EUDR - EU Timber Regulations / EU Deforestation Regulation | R9: 0 | S9: 0 | T9: Nature Activity Reports | U9: 0 | V9: 0
F10: VOCs - Volatile Organic Compounds | G10: 0 | H10: 0 | I10: 0 | J10: 0 | K10: VOCs - Volatile Organic Compounds | L10: 0 | M10: 0 | N10: Disposal at Sea | O10: 0 | P10: 0 | Q10: SUPs - Movement and Importation | R10: 0 | S10: 0 | T10: CCTVs | U10: 0 | V10: 0
F11: MCPs - Medium Combustion Plants | G11: 0 | H11: 0 | I11: 0 | J11: 0 | K11: MCPs - Medium Combustion Plants | L11: 0 | M11: 0 | Q11: SUPs - Placing on the Market | R11: 0 | S11: 0 | T11: EP Consultations | U11: 0 | V11: 0
C12: ADDITIONAL INFORMATION This data will be collected by CED Operations/Admin: - Cases Opened during reporting year - Cases Closed only during reporting year (including cases opened in years prior to the reporting year) | F12: Maintenance Industries | G12: 0 | H12: 0 | I12: 0 | J12: 0 | K12: Maintenance Industries | L12: 0 | M12: 0 | T12: Strategy / Policy Consultations | U12: 0 | V12: 0
F13: Quarry drone surveys | G13: 0 | H13: 0 | I13: 0 | J13: 0 | K13: Quarry drone surveys | L13: 0 | M13: 0 | T13: Smoking Control on Beaches | U13: 0 | V13: 0
F14: Waste Dumping | G14: 0 | H14: 0 | I14: 0 | J14: 0 | K14: Waste Dumping | L14: 0 | M14: 0 | T14: Not ERA Remit | U14: 0 | V14: 0
F15: Waste Incineration | G15: 0 | H15: 0 | I15: 0 | J15: 0 | K15: Waste Incineration | L15: 0 | M15: 0
F16: Farm operations | G16: 0 | H16: 0 | I16: 0 | J16: 0 | K16: Farm operations | L16: 0 | M16: 0
F17: Aquaculture | G17: 0 | H17: 0 | I17: 0 | J17: 0 | K17: Aquaculture | L17: 0 | M17: 0
F18: COMAH - Control of Major Accident Hazards | G18: 0 | H18: 0 | I18: 0 | J18: 0 | K18: COMAH - Control of Major Accident Hazards | L18: 0 | M18: 0
F19: LCPs, STPs, ROs, NFRP and Port Facilities | G19: 0 | H19: 0 | I19: 0 | J19: 0 | K19: LCPs, STPs, ROs, NFRP and Port Facilities | L19: 0 | M19: 0
F20: Fuel Terminals | G20: 0 | H20: 0 | I20: 0 | J20: 0 | K20: Fuel Terminals | L20: 0 | M20: 0
F21: Construction / Demolition -related marine pollution | G21: 0 | H21: 0 | I21: 0 | J21: 0 | K21: Construction / Demolition -related marine pollution | L21: 0 | M21: 0
F22: Hotels and hospitality | G22: 0 | H22: 0 | I22: 0 | J22: 0 | K22: Hotels and hospitality | L22: 0 | M22: 0
F23: Groundwater (Boreholes) | G23: 0 | H23: 0 | I23: 0 | J23: 0 | K23: Groundwater (Boreholes) | L23: 0 | M23: 0
F24: Sewage in sea | G24: 0 | H24: 0 | I24: 0 | J24: 0 | K24: Sewage in sea | L24: 0 | M24: 0
F25: Exceedances in emissions/discharges | G25: 0 | H25: 0 | I25: 0 | J25: 0 | K25: Exceedances in emissions/discharges | L25: 0 | M25: 0
F26: Tree Protection | G26: 0 | H26: 0 | I26: 0 | J26: 0 | K26: Tree Protection | L26: 0 | M26: 0
... F34: Oil Spills / Major Incidents | G34: 0 | H34: 0 | I34: 0 | J34: 0 | K34: Oil Spills / Major Incidents | L34: 0 | M34: 0
B38: 2 | C38: Statistics Item | D38: Total | F38: North Region | K38: South Region | N38: Market Surveillance | Q38: Border Control | T38: Operations + Admin
C39: Total Orders Issued and Closed | D39: Issued | E39: Closed | G39: Issued - Malta | H39: Issued - Gozo | I39: Closed - Malta | J39: Closed - Gozo | L39: Issued | M39: Closed | O39: Issued | P39: Closed | R39: Issued | S39: Closed | U39: Issued | V39: Closed
D40: =SUM(G40,H40,L40,O40,R40,U40) -> 0 | E40: =SUM(I40,J40,M40,P40,S40,V40) -> 0 | G40: =SUM(G41:G70) -> 0 | H40: =SUM(H41:H70) -> 0 | I40: =SUM(I41:I70) -> 0 | J40: =SUM(J41:J70) -> 0 | L40: =SUM(L41:L70) -> 0 | M40: =SUM(M41:M70) -> 0 | O40: =SUM(O41:O46) -> 0 | P40: =SUM(P41:P46) -> 0 | R40: =SUM(R41:R47) -> 0 | S40: =SUM(S41:S47) -> 0 | U40: =SUM(U41:U49) -> 0 | V40: =SUM(V41:V49) -> 0
F41: Waste Management Facilities | G41: 0 | H41: 0 | I41: 0 | J41: 0 | K41: Waste Management Facilities | L41: 0 | M41: 0 | N41: Local Waste Transfers – Waste Carriers | O41: 0 | P41: 0 | Q41: Wildlife trade / Species Protection & Control border movements | R41: 0 | S41: 0 | T41: Development / Development permit related | U41: 0 | V41: 0
F42: Quarries and related Industries | G42: 0 | H42: 0 | I42: 0 | J42: 0 | K42: Quarries and related Industries | L42: 0 | M42: 0 | N42: Shipments of waste | O42: 0 | P42: 0 | Q42: Wildlife Trade / Species Protection & Control excluding border movements | R42: 0 | S42: 0 | T42: AERs - Annual Environment Reports | U42: 0 | V42: 0
F43: Manufacturing operations | G43: 0 | H43: 0 | I43: 0 | J43: 0 | K43: Manufacturing operations | L43: 0 | M43: 0 | N43: Recycling points | O43: 0 | P43: 0 | Q43: GMOs - Genetically Modified Organisms | R43: 0 | S43: 0 | T43: Litter | U43: 0 | V43: 0
F44: Pharmaceutical industry | G44: 0 | H44: 0 | I44: 0 | J44: 0 | K44: Pharmaceutical industry | L44: 0 | M44: 0 | N44: Extended Producer Responsibility | O44: 0 | P44: 0 | Q44: FLEGT - Forest Law Enforcement, Governance and Trade | R44: 0 | S44: 0 | T44: Development Permit Clearances | U44: 0 | V44: 0
F45: Petrol Stations | G45: 0 | H45: 0 | I45: 0 | J45: 0 | K45: Petrol Stations | L45: 0 | M45: 0 | N45: Consignment notes | O45: 0 | P45: 0 | Q45: EUTR/EUDR - EU Timber Regulations / EU Deforestation Regulation | R45: 0 | S45: 0 | T45: Nature Activity Reports | U45: 0 | V45: 0
F46: VOCs - Volatile Organic Compounds | G46: 0 | H46: 0 | I46: 0 | J46: 0 | K46: VOCs - Volatile Organic Compounds | L46: 0 | M46: 0 | N46: Disposal at Sea | O46: 0 | P46: 0 | Q46: SUPs - Movement and Importation | R46: 0 | S46: 0 | T46: CCTVs | U46: 0 | V46: 0
F47: MCPs - Medium Combustion Plants | G47: 0 | H47: 0 | I47: 0 | J47: 0 | K47: MCPs - Medium Combustion Plants | L47: 0 | M47: 0 | Q47: SUPs - Placing on the Market | R47: 0 | S47: 0 | T47: EP Consultations | U47: 0 | V47: 0
F48: Maintenance Industries | G48: 0 | H48: 0 | I48: 0 | J48: 0 | K48: Maintenance Industries | L48: 0 | M48: 0 | T48: Strategy / Policy Consultations | U48: 0 | V48: 0
F49: Quarry drone surveys | G49: 0 | H49: 0 | I49: 0 | J49: 0 | K49: Quarry drone surveys | L49: 0 | M49: 0 | T49: Smoking Control on Beaches | U49: 0 | V49: 0
F50: Waste Dumping | G50: 0 | H50: 0 | I50: 0 | J50: 0 | K50: Waste Dumping | L50: 0 | M50: 0 | T50: Not ERA Remit | U50: 0 | V50: 0
C51: ADDITIONAL INFORMATION Issued ORDERS should only be limited to reporting year. Closed ORDERS should include all ORDERS closed in reporting year. | F51: Waste Incineration | G51: 0 | H51: 0 | I51: 0 | J51: 0 | K51: Waste Incineration | L51: 0 | M51: 0
...

Sheet February
B2: 1 | C2: Statistics Item | D2: Total | F2: North Region | K2: South Region | N2: Market Surveillance | Q2: Border Control | T2: Operations + Admin
C3: Total Cases and/or Complaints (Internal & External) received and closed | D3: Opened | E3: Closed | G3: Opened - Malta | H3: Opened - Gozo | I3: Closed - Malta | J3: Closed - Gozo | L3: Opened | M3: Closed | O3: Opened | P3: Closed | R3: Opened | S3: Closed | U3: Opened | V3: Closed
D4: =SUM(G4,H4,L4,O4,R4,U4) -> 0 | E4: =SUM(I4,J4,M4,P4,S4,V4) -> 0 | G4: =SUM(G5:G34) -> 0 | H4: =SUM(H5:H34) -> 0 | I4: =SUM(I5:I34) -> 0 | J4: =SUM(J5:J34) -> 0 | L4: =SUM(L5:L34) -> 0 | M4: =SUM(M5:M34) -> 0 | O4: =SUM(O5:O10) -> 0 | P4: =SUM(P5:P10) -> 0 | R4: =SUM(R5:R11) -> 0 | S4: =SUM(S5:S11) -> 0 | U4: =SUM(U5:U13) -> 0 | V4: =SUM(V5:V13) -> 0
F5: Waste Management Facilities | G5: 0 | H5: 0 | I5: 0 | J5: 0 | K5: Waste Management Facilities | L5: 0 | M5: 0 | N5: Local Waste Transfers – Waste Carriers | O5: 0 | P5: 0 | Q5: Wildlife trade / Species Protection & Control border movements | R5: 0 | S5: 0 | T5: Development / Development permit related | U5: 0 | V5: 0
F6: Quarries and related Industries | G6: 0 | H6: 0 | I6: 0 | J6: 0 | K6: Quarries and related Industries | L6: 0 | M6: 0 | N6: Shipments of waste | O6: 0 | P6: 0 | Q6: Wildlife Trade / Species Protection & Control excluding border movements | R6: 0 | S6: 0 | T6: AERs - Annual Environment Reports | U6: 0 | V6: 0
F7: Manufacturing operations | G7: 0 | H7: 0 | I7: 0 | J7: 0 | K7: Manufacturing operations | L7: 0 | M7: 0 | N7: Recycling points | O7: 0 | P7: 0 | Q7: GMOs - Genetically Modified Organisms | R7: 0 | S7: 0 | T7: Litter | U7: 0 | V7: 0
F8: Pharmaceutical industry | G8: 0 | H8: 0 | I8: 0 | J8: 0 | K8: Pharmaceutical industry | L8: 0 | M8: 0 | N8: Extended Producer Responsibility | O8: 0 | P8: 0 | Q8: FLEGT - Forest Law Enforcement, Governance and Trade | R8: 0 | S8: 0 | T8: Development Permit Clearances | U8: 0 | V8: 0
F9: Petrol Stations | G9: 0 | H9: 0 | I9: 0 | J9: 0 | K9: Petrol Stations | L9: 0 | M9: 0 | N9: Consignment notes | O9: 0 | P9: 0 | Q9: EUTR/EUDR - EU Timber Regulations / EU Deforestation Regulation | R9: 0 | S9: 0 | T9: Nature Activity Reports | U9: 0 | V9: 0
F10: VOCs - Volatile Organic Compounds | G10: 0 | H10: 0 | I10: 0 | J10: 0 | K10: VOCs - Volatile Organic Compounds | L10: 0 | M10: 0 | N10: Disposal at Sea | O10: 0 | P10: 0 | Q10: SUPs - Movement and Importation | R10: 0 | S10: 0 | T10: CCTVs | U10: 0 | V10: 0
F11: MCPs - Medium Combustion Plants | G11: 0 | H11: 0 | I11: 0 | J11: 0 | K11: MCPs - Medium Combustion Plants | L11: 0 | M11: 0 | Q11: SUPs - Placing on the Market | R11: 0 | S11: 0 | T11: EP Consultations | U11: 0 | V11: 0
C12: ADDITIONAL INFORMATION This data will be collected by CED Operations/Admin: - Cases Opened during reporting year - Cases Closed only during reporting year (including cases opened in years prior to the reporting year) | F12: Maintenance Industries | G12: 0 | H12: 0 | I12: 0 | J12: 0 | K12: Maintenance Industries | L12: 0 | M12: 0 | T12: Strategy / Policy Consultations | U12: 0 | V12: 0
F13: Quarry drone surveys | G13: 0 | H13: 0 | I13: 0 | J13: 0 | K13: Quarry drone surveys | L13: 0 | M13: 0 | T13: Smoking Control on Beaches | U13: 0 | V13: 0
F14: Waste Dumping | G14: 0 | H14: 0 | I14: 0 | J14: 0 | K14: Waste Dumping | L14: 0 | M14: 0 | T14: Not ERA Remit | U14: 0 | V14: 0
F15: Waste Incineration | G15: 0 | H15: 0 | I15: 0 | J15: 0 | K15: Waste Incineration | L15: 0 | M15: 0
F16: Farm operations | G16: 0 | H16: 0 | I16: 0 | J16: 0 | K16: Farm operations | L16: 0 | M16: 0
F17: Aquaculture | G17: 0 | H17: 0 | I17: 0 | J17: 0 | K17: Aquaculture | L17: 0 | M17: 0
F18: COMAH - Control of Major Accident Hazards | G18: 0 | H18: 0 | I18: 0 | J18: 0 | K18: COMAH - Control of Major Accident Hazards | L18: 0 | M18: 0
F19: LCPs, STPs, ROs, NFRP and Port Facilities | G19: 0 | H19: 0 | I19: 0 | J19: 0 | K19: LCPs, STPs, ROs, NFRP and Port Facilities | L19: 0 | M19: 0
F20: Fuel Terminals | G20: 0 | H20: 0 | I20: 0 | J20: 0 | K20: Fuel Terminals | L20: 0 | M20: 0
F21: Construction / Demolition -related marine pollution | G21: 0 | H21: 0 | I21: 0 | J21: 0 | K21: Construction / Demolition -related marine pollution | L21: 0 | M21: 0
F22: Hotels and hospitality | G22: 0 | H22: 0 | I22: 0 | J22: 0 | K22: Hotels and hospitality | L22: 0 | M22: 0
F23: Groundwater (Boreholes) | G23: 0 | H23: 0 | I23: 0 | J23: 0 | K23: Groundwater (Boreholes) | L23: 0 | M23: 0
F24: Sewage in sea | G24: 0 | H24: 0 | I24: 0 | J24: 0 | K24: Sewage in sea | L24: 0 | M24: 0
F25: Exceedances in emissions/discharges | G25: 0 | H25: 0 | I25: 0 | J25: 0 | K25: Exceedances in emissions/discharges | L25: 0 | M25: 0
F26: Tree Protection | G26: 0 | H26: 0 | I26: 0 | J26: 0 | K26: Tree Protection | L26: 0 | M26: 0
... F34: Oil Spills / Major Incidents | G34: 0 | H34: 0 | I34: 0 | J34: 0 | K34: Oil Spills / Major Incidents | L34: 0 | M34: 0
B38: 2 | C38: Statistics Item | D38: Total | F38: North Region | K38: South Region | N38: Market Surveillance | Q38: Border Control | T38: Operations + Admin
C39: Total Orders Issued and Closed | D39: Issued | E39: Closed | G39: Issued - Malta | H39: Issued - Gozo | I39: Closed - Malta | J39: Closed - Gozo | L39: Issued | M39: Closed | O39: Issued | P39: Closed | R39: Issued | S39: Closed | U39: Issued | V39: Closed
D40: =SUM(G40,H40,L40,O40,R40,U40) -> 0 | E40: =SUM(I40,J40,M40,P40,S40,V40) -> 0 | G40: =SUM(G41:G70) -> 0 | H40: =SUM(H41:H70) -> 0 | I40: =SUM(I41:I70) -> 0 | J40: =SUM(J41:J70) -> 0 | L40: =SUM(L41:L70) -> 0 | M40: =SUM(M41:M70) -> 0 | O40: =SUM(O41:O46) -> 0 | P40: =SUM(P41:P46) -> 0 | R40: =SUM(R41:R47) -> 0 | S40: =SUM(S41:S47) -> 0 | U40: =SUM(U41:U49) -> 0 | V40: =SUM(V41:V49) -> 0
F41: Waste Management Facilities | G41: 0 | H41: 0 | I41: 0 | J41: 0 | K41: Waste Management Facilities | L41: 0 | M41: 0 | N41: Local Waste Transfers – Waste Carriers | O41: 0 | P41: 0 | Q41: Wildlife trade / Species Protection & Control border movements | R41: 0 | S41: 0 | T41: Development / Development permit related | U41: 0 | V41: 0
F42: Quarries and related Industries | G42: 0 | H42: 0 | I42: 0 | J42: 0 | K42: Quarries and related Industries | L42: 0 | M42: 0 | N42: Shipments of waste | O42: 0 | P42: 0 | Q42: Wildlife Trade / Species Protection & Control excluding border movements | R42: 0 | S42: 0 | T42: AERs - Annual Environment Reports | U42: 0 | V42: 0
F43: Manufacturing operations | G43: 0 | H43: 0 | I43: 0 | J43: 0 | K43: Manufacturing operations | L43: 0 | M43: 0 | N43: Recycling points | O43: 0 | P43: 0 | Q43: GMOs - Genetically Modified Organisms | R43: 0 | S43: 0 | T43: Litter | U43: 0 | V43: 0
F44: Pharmaceutical industry | G44: 0 | H44: 0 | I44: 0 | J44: 0 | K44: Pharmaceutical industry | L44: 0 | M44: 0 | N44: Extended Producer Responsibility | O44: 0 | P44: 0 | Q44: FLEGT - Forest Law Enforcement, Governance and Trade | R44: 0 | S44: 0 | T44: Development Permit Clearances | U44: 0 | V44: 0
F45: Petrol Stations | G45: 0 | H45: 0 | I45: 0 | J45: 0 | K45: Petrol Stations | L45: 0 | M45: 0 | N45: Consignment notes | O45: 0 | P45: 0 | Q45: EUTR/EUDR - EU Timber Regulations / EU Deforestation Regulation | R45: 0 | S45: 0 | T45: Nature Activity Reports | U45: 0 | V45: 0
F46: VOCs - Volatile Organic Compounds | G46: 0 | H46: 0 | I46: 0 | J46: 0 | K46: VOCs - Volatile Organic Compounds | L46: 0 | M46: 0 | N46: Disposal at Sea | O46: 0 | P46: 0 | Q46: SUPs - Movement and Importation | R46: 0 | S46: 0 | T46: CCTVs | U46: 0 | V46: 0
F47: MCPs - Medium Combustion Plants | G47: 0 | H47: 0 | I47: 0 | J47: 0 | K47: MCPs - Medium Combustion Plants | L47: 0 | M47: 0 | Q47: SUPs - Placing on the Market | R47: 0 | S47: 0 | T47: EP Consultations | U47: 0 | V47: 0
F48: Maintenance Industries | G48: 0 | H48: 0 | I48: 0 | J48: 0 | K48: Maintenance Industries | L48: 0 | M48: 0 | T48: Strategy / Policy Consultations | U48: 0 | V48: 0
F49: Quarry drone surveys | G49: 0 | H49: 0 | I49: 0 | J49: 0 | K49: Quarry drone surveys | L49: 0 | M49: 0 | T49: Smoking Control on Beaches | U49: 0 | V49: 0
F50: Waste Dumping | G50: 0 | H50: 0 | I50: 0 | J50: 0 | K50: Waste Dumping | L50: 0 | M50: 0 | T50: Not ERA Remit | U50: 0 | V50: 0
C51: ADDITIONAL INFORMATION Issued ORDERS should only be limited to reporting year. Closed ORDERS should include all ORDERS closed in reporting year. | F51: Waste Incineration | G51: 0 | H51: 0 | I51: 0 | J51: 0 | K51: Waste Incineration | L51: 0 | M51: 0
...

Sheet March
B2: 1 | C2: Statistics Item | D2: Total | F2: North Region | K2: South Region | N2: Market Surveillance | Q2: Border Control | T2: Operations + Admin
C3: Total Cases and/or Complaints (Internal & External) received and closed | D3: Opened | E3: Closed | G3: Opened - Malta | H3: Opened - Gozo | I3: Closed - Malta | J3: Closed - Gozo | L3: Opened | M3: Closed | O3: Opened | P3: Closed | R3: Opened | S3: Closed | U3: Opened | V3: Closed
D4: =SUM(G4,H4,L4,O4,R4,U4) -> 0 | E4: =SUM(I4,J4,M4,P4,S4,V4) -> 0 | G4: =SUM(G5:G34) -> 0 | H4: =SUM(H5:H34) -> 0 | I4: =SUM(I5:I34) -> 0 | J4: =SUM(J5:J34) -> 0 | L4: =SUM(L5:L34) -> 0 | M4: =SUM(M5:M34) -> 0 | O4: =SUM(O5:O10) -> 0 | P4: =SUM(P5:P10) -> 0 | R4: =SUM(R5:R11) -> 0 | S4: =SUM(S5:S11) -> 0 | U4: =SUM(U5:U13) -> 0 | V4: =SUM(V5:V13) -> 0
F5: Waste Management Facilities | G5: 0 | H5: 0 | I5: 0 | J5: 0 | K5: Waste Management Facilities | L5: 0 | M5: 0 | N5: Local Waste Transfers – Waste Carriers | O5: 0 | P5: 0 | Q5: Wildlife trade / Species Protection & Control border movements | R5: 0 | S5: 0 | T5: Development / Development permit related | U5: 0 | V5: 0
F6: Quarries and related Industries | G6: 0 | H6: 0 | I6: 0 | J6: 0 | K6: Quarries and related Industries | L6: 0 | M6: 0 | N6: Shipments of waste | O6: 0 | P6: 0 | Q6: Wildlife Trade / Species Protection & Control excluding border movements | R6: 0 | S6: 0 | T6: AERs - Annual Environment Reports | U6: 0 | V6: 0
F7: Manufacturing operations | G7: 0 | H7: 0 | I7: 0 | J7: 0 | K7: Manufacturing operations | L7: 0 | M7: 0 | N7: Recycling points | O7: 0 | P7: 0 | Q7: GMOs - Genetically Modified Organisms | R7: 0 | S7: 0 | T7: Litter | U7: 0 | V7: 0
F8: Pharmaceutical industry | G8: 0 | H8: 0 | I8: 0 | J8: 0 | K8: Pharmaceutical industry | L8: 0 | M8: 0 | N8: Extended Producer Responsibility | O8: 0 | P8: 0 | Q8: FLEGT - Forest Law Enforcement, Governance and Trade | R8: 0 | S8: 0 | T8: Development Permit Clearances | U8: 0 | V8: 0
F9: Petrol Stations | G9: 0 | H9: 0 | I9: 0 | J9: 0 | K9: Petrol Stations | L9: 0 | M9: 0 | N9: Consignment notes | O9: 0 | P9: 0 | Q9: EUTR/EUDR - EU Timber Regulations / EU Deforestation Regulation | R9: 0 | S9: 0 | T9: Nature Activity Reports | U9: 0 | V9: 0
F10: VOCs - Volatile Organic Compounds | G10: 0 | H10: 0 | I10: 0 | J10: 0 | K10: VOCs - Volatile Organic Compounds | L10: 0 | M10: 0 | N10: Disposal at Sea | O10: 0 | P10: 0 | Q10: SUPs - Movement and Importation | R10: 0 | S10: 0 | T10: CCTVs | U10: 0 | V10: 0
F11: MCPs - Medium Combustion Plants | G11: 0 | H11: 0 | I11: 0 | J11: 0 | K11: MCPs - Medium Combustion Plants | L11: 0 | M11: 0 | Q11: SUPs - Placing on the Market | R11: 0 | S11: 0 | T11: EP Consultations | U11: 0 | V11: 0
C12: ADDITIONAL INFORMATION This data will be collected by CED Operations/Admin: - Cases Opened during reporting year - Cases Closed only during reporting year (including cases opened in years prior to the reporting year) | F12: Maintenance Industries | G12: 0 | H12: 0 | I12: 0 | J12: 0 | K12: Maintenance Industries | L12: 0 | M12: 0 | T12: Strategy / Policy Consultations | U12: 0 | V12: 0
F13: Quarry drone surveys | G13: 0 | H13: 0 | I13: 0 | J13: 0 | K13: Quarry drone surveys | L13: 0 | M13: 0 | T13: Smoking Control on Beaches | U13: 0 | V13: 0
F14: Waste Dumping | G14: 0 | H14: 0 | I14: 0 | J14: 0 | K14: Waste Dumping | L14: 0 | M14: 0 | T14: Not ERA Remit | U14: 0 | V14: 0
F15: Waste Incineration | G15: 0 | H15: 0 | I15: 0 | J15: 0 | K15: Waste Incineration | L15: 0 | M15: 0
F16: Farm operations | G16: 0 | H16: 0 | I16: 0 | J16: 0 | K16: Farm operations | L16: 0 | M16: 0
F17: Aquaculture | G17: 0 | H17: 0 | I17: 0 | J17: 0 | K17: Aquaculture | L17: 0 | M17: 0
F18: COMAH - Control of Major Accident Hazards | G18: 0 | H18: 0 | I18: 0 | J18: 0 | K18: COMAH - Control of Major Accident Hazards | L18: 0 | M18: 0
F19: LCPs, STPs, ROs, NFRP and Port Facilities | G19: 0 | H19: 0 | I19: 0 | J19: 0 | K19: LCPs, STPs, ROs, NFRP and Port Facilities | L19: 0 | M19: 0
F20: Fuel Terminals | G20: 0 | H20: 0 | I20: 0 | J20: 0 | K20: Fuel Terminals | L20: 0 | M20: 0
F21: Construction / Demolition -related marine pollution | G21: 0 | H21: 0 | I21: 0 | J21: 0 | K21: Construction / Demolition -related marine pollution | L21: 0 | M21: 0
F22: Hotels and hospitality | G22: 0 | H22: 0 | I22: 0 | J22: 0 | K22: Hotels and hospitality | L22: 0 | M22: 0
F23: Groundwater (Boreholes) | G23: 0 | H23: 0 | I23: 0 | J23: 0 | K23: Groundwater (Boreholes) | L23: 0 | M23: 0
F24: Sewage in sea | G24: 0 | H24: 0 | I24: 0 | J24: 0 | K24: Sewage in sea | L24: 0 | M24: 0
F25: Exceedances in emissions/discharges | G25: 0 | H25: 0 | I25: 0 | J25: 0 | K25: Exceedances in emissions/discharges | L25: 0 | M25: 0
F26: Tree Protection | G26: 0 | H26: 0 | I26: 0 | J26: 0 | K26: Tree Protection | L26: 0 | M26: 0
... F34: Oil Spills / Major Incidents | G34: 0 | H34: 0 | I34: 0 | J34: 0 | K34: Oil Spills / Major Incidents | L34: 0 | M34: 0
B38: 2 | C38: Statistics Item | D38: Total | F38: North Region | K38: South Region | N38: Market Surveillance | Q38: Border Control | T38: Operations + Admin
C39: Total Orders Issued and Closed | D39: Issued | E39: Closed | G39: Issued - Malta | H39: Issued - Gozo | I39: Closed - Malta | J39: Closed - Gozo | L39: Issued | M39: Closed | O39: Issued | P39: Closed | R39: Issued | S39: Closed | U39: Issued | V39: Closed
D40: =SUM(G40,H40,L40,O40,R40,U40) -> 0 | E40: =SUM(I40,J40,M40,P40,S40,V40) -> 0 | G40: =SUM(G41:G70) -> 0 | H40: =SUM(H41:H70) -> 0 | I40: =SUM(I41:I70) -> 0 | J40: =SUM(J41:J70) -> 0 | L40: =SUM(L41:L70) -> 0 | M40: =SUM(M41:M70) -> 0 | O40: =SUM(O41:O46) -> 0 | P40: =SUM(P41:P46) -> 0 | R40: =SUM(R41:R47) -> 0 | S40: =SUM(S41:S47) -> 0 | U40: =SUM(U41:U49) -> 0 | V40: =SUM(V41:V49) -> 0
F41: Waste Management Facilities | G41: 0 | H41: 0 | I41: 0 | J41: 0 | K41: Waste Management Facilities | L41: 0 | M41: 0 | N41: Local Waste Transfers – Waste Carriers | O41: 0 | P41: 0 | Q41: Wildlife trade / Species Protection & Control border movements | R41: 0 | S41: 0 | T41: Development / Development permit related | U41: 0 | V41: 0
F42: Quarries and related Industries | G42: 0 | H42: 0 | I42: 0 | J42: 0 | K42: Quarries and related Industries | L42: 0 | M42: 0 | N42: Shipments of waste | O42: 0 | P42: 0 | Q42: Wildlife Trade / Species Protection & Control excluding border movements | R42: 0 | S42: 0 | T42: AERs - Annual Environment Reports | U42: 0 | V42: 0
F43: Manufacturing operations | G43: 0 | H43: 0 | I43: 0 | J43: 0 | K43: Manufacturing operations | L43: 0 | M43: 0 | N43: Recycling points | O43: 0 | P43: 0 | Q43: GMOs - Genetically Modified Organisms | R43: 0 | S43: 0 | T43: Litter | U43: 0 | V43: 0
F44: Pharmaceutical industry | G44: 0 | H44: 0 | I44: 0 | J44: 0 | K44: Pharmaceutical industry | L44: 0 | M44: 0 | N44: Extended Producer Responsibility | O44: 0 | P44: 0 | Q44: FLEGT - Forest Law Enforcement, Governance and Trade | R44: 0 | S44: 0 | T44: Development Permit Clearances | U44: 0 | V44: 0
F45: Petrol Stations | G45: 0 | H45: 0 | I45: 0 | J45: 0 | K45: Petrol Stations | L45: 0 | M45: 0 | N45: Consignment notes | O45: 0 | P45: 0 | Q45: EUTR/EUDR - EU Timber Regulations / EU Deforestation Regulation | R45: 0 | S45: 0 | T45: Nature Activity Reports | U45: 0 | V45: 0
F46: VOCs - Volatile Organic Compounds | G46: 0 | H46: 0 | I46: 0 | J46: 0 | K46: VOCs - Volatile Organic Compounds | L46: 0 | M46: 0 | N46: Disposal at Sea | O46: 0 | P46: 0 | Q46: SUPs - Movement and Importation | R46: 0 | S46: 0 | T46: CCTVs | U46: 0 | V46: 0
F47: MCPs - Medium Combustion Plants | G47: 0 | H47: 0 | I47: 0 | J47: 0 | K47: MCPs - Medium Combustion Plants | L47: 0 | M47: 0 | Q47: SUPs - Placing on the Market | R47: 0 | S47: 0 | T47: EP Consultations | U47: 0 | V47: 0
F48: Maintenance Industries | G48: 0 | H48: 0 | I48: 0 | J48: 0 | K48: Maintenance Industries | L48: 0 | M48: 0 | T48: Strategy / Policy Consultations | U48: 0 | V48: 0
F49: Quarry drone surveys | G49: 0 | H49: 0 | I49: 0 | J49: 0 | K49: Quarry drone surveys | L49: 0 | M49: 0 | T49: Smoking Control on Beaches | U49: 0 | V49: 0
F50: Waste Dumping | G50: 0 | H50: 0 | I50: 0 | J50: 0 | K50: Waste Dumping | L50: 0 | M50: 0 | T50: Not ERA Remit | U50: 0 | V50: 0
C51: ADDITIONAL INFORMATION Issued ORDERS should only be limited to reporting year. Closed ORDERS should include all ORDERS closed in reporting year. | F51: Waste Incineration | G51: 0 | H51: 0 | I51: 0 | J51: 0 | K51: Waste Incineration | L51: 0 | M51: 0
...

Sheet Q1
B2: 1 | C2: Statistics Item | D2: Total | F2: North Region | K2: South Region | N2: Market Surveillance | Q2: Border Control | T2: Operations + Admin
C3: Total Cases and/or Complaints (Internal & External) received and closed | D3: Opened | E3: Closed | G3: Opened - Malta | H3: Opened - Gozo | I3: Closed - Malta | J3: Closed - Gozo | L3: Opened | M3: Closed | O3: Opened | P3: Closed | R3: Opened | S3: Closed | U3: Opened | V3: Closed
D4: =SUM(G4,H4,L4,O4,R4,U4) -> 0 | E4: =SUM(I4,J4,M4,P4,S4,V4) -> 0 | G4: =SUM(G5:G34) -> 0 | H4: =SUM(H5:H34) -> 0 | I4: =SUM(I5:I34) -> 0 | J4: =SUM(J5:J34) -> 0 | L4: =SUM(L5:L34) -> 0 | M4: =SUM(M5:M34) -> 0 | O4: =SUM(O5:O10) -> 0 | P4: =SUM(P5:P10) -> 0 | R4: =SUM(R5:R11) -> 0 | S4: =SUM(S5:S11) -> 0 | U4: =SUM(U5:U13) -> 0 | V4: =SUM(V5:V13) -> 0
F5: Waste Management Facilities | G5: 0 | H5: 0 | I5: 0 | J5: 0 | K5: Waste Management Facilities | L5: 0 | M5: 0 | N5: Local Waste Transfers – Waste Carriers | O5: 0 | P5: 0 | Q5: Wildlife trade / Species Protection & Control border movements | R5: 0 | S5: 0 | T5: Development / Development permit related | U5: 0 | V5: 0
F6: Quarries and related Industries | G6: 0 | H6: 0 | I6: 0 | J6: 0 | K6: Quarries and related Industries | L6: 0 | M6: 0 | N6: Shipments of waste | O6: 0 | P6: 0 | Q6: Wildlife Trade / Species Protection & Control excluding border movements | R6: 0 | S6: 0 | T6: AERs - Annual Environment Reports | U6: 0 | V6: 0
F7: Manufacturing operations | G7: 0 | H7: 0 | I7: 0 | J7: 0 | K7: Manufacturing operations | L7: 0 | M7: 0 | N7: Recycling points | O7: 0 | P7: 0 | Q7: GMOs - Genetically Modified Organisms | R7: 0 | S7: 0 | T7: Litter | U7: 0 | V7: 0
F8: Pharmaceutical industry | G8: 0 | H8: 0 | I8: 0 | J8: 0 | K8: Pharmaceutical industry | L8: 0 | M8: 0 | N8: Extended Producer Responsibility | O8: 0 | P8: 0 | Q8: FLEGT - Forest Law Enforcement, Governance and Trade | R8: 0 | S8: 0 | T8: Development Permit Clearances | U8: 0 | V8: 0
F9: Petrol Stations | G9: 0 | H9: 0 | I9: 0 | J9: 0 | K9: Petrol Stations | L9: 0 | M9: 0 | N9: Consignment notes | O9: 0 | P9: 0 | Q9: EUTR/EUDR - EU Timber Regulations / EU Deforestation Regulation | R9: 0 | S9: 0 | T9: Nature Activity Reports | U9: 0 | V9: 0
F10: VOCs - Volatile Organic Compounds | G10: 0 | H10: 0 | I10: 0 | J10: 0 | K10: VOCs - Volatile Organic Compounds | L10: 0 | M10: 0 | N10: Disposal at Sea | O10: 0 | P10: 0 | Q10: SUPs - Movement and Importation | R10: 0 | S10: 0 | T10: CCTVs | U10: 0 | V10: 0
F11: MCPs - Medium Combustion Plants | G11: 0 | H11: 0 | I11: 0 | J11: 0 | K11: MCPs - Medium Combustion Plants | L11: 0 | M11: 0 | Q11: SUPs - Placing on the Market | R11: 0 | S11: 0 | T11: EP Consultations | U11: 0 | V11: 0
C12: ADDITIONAL INFORMATION This data will be collected by CED Operations/Admin: - Cases Opened during reporting year - Cases Closed only during reporting year (including cases opened in years prior to the reporting year) | F12: Maintenance Industries | G12: 0 | H12: 0 | I12: 0 | J12: 0 | K12: Maintenance Industries | L12: 0 | M12: 0 | T12: Strategy / Policy Consultations | U12: 0 | V12: 0
F13: Quarry drone surveys | G13: 0 | H13: 0 | I13: 0 | J13: 0 | K13: Quarry drone surveys | L13: 0 | M13: 0 | T13: Smoking Control on Beaches | U13: 0 | V13: 0
F14: Waste Dumping | G14: 0 | H14: 0 | I14: 0 | J14: 0 | K14: Waste Dumping | L14: 0 | M14: 0 | T14: Not ERA Remit | U14: 0 | V14: 0
F15: Waste Incineration | G15: 0 | H15: 0 | I15: 0 | J15: 0 | K15: Waste Incineration | L15: 0 | M15: 0
F16: Farm operations | G16: 0 | H16: 0 | I16: 0 | J16: 0 | K16: Farm operations | L16: 0 | M16: 0
F17: Aquaculture | G17: 0 | H17: 0 | I17: 0 | J17: 0 | K17: Aquaculture | L17: 0 | M17: 0
F18: COMAH - Control of Major Accident Hazards | G18: 0 | H18: 0 | I18: 0 | J18: 0 | K18: COMAH - Control of Major Accident Hazards | L18: 0 | M18: 0
F19: LCPs, STPs, ROs, NFRP and Port Facilities | G19: 0 | H19: 0 | I19: 0 | J19: 0 | K19: LCPs, STPs, ROs, NFRP and Port Facilities | L19: 0 | M19: 0
F20: Fuel Terminals | G20: 0 | H20: 0 | I20: 0 | J20: 0 | K20: Fuel Terminals | L20: 0 | M20: 0
F21: Construction / Demolition -related marine pollution | G21: 0 | H21: 0 | I21: 0 | J21: 0 | K21: Construction / Demolition -related marine pollution | L21: 0 | M21: 0
F22: Hotels and hospitality | G22: 0 | H22: 0 | I22: 0 | J22: 0 | K22: Hotels and hospitality | L22: 0 | M22: 0
F23: Groundwater (Boreholes) | G23: 0 | H23: 0 | I23: 0 | J23: 0 | K23: Groundwater (Boreholes) | L23: 0 | M23: 0
F24: Sewage in sea | G24: 0 | H24: 0 | I24: 0 | J24: 0 | K24: Sewage in sea | L24: 0 | M24: 0
F25: Exceedances in emissions/discharges | G25: 0 | H25: 0 | I25: 0 | J25: 0 | K25: Exceedances in emissions/discharges | L25: 0 | M25: 0
F26: Tree Protection | G26: 0 | H26: 0 | I26: 0 | J26: 0 | K26: Tree Protection | L26: 0 | M26: 0
... F34: Oil Spills / Major Incidents | G34: 0 | H34: 0 | I34: 0 | J34: 0 | K34: Oil Spills / Major Incidents | L34: 0 | M34: 0
B38: 2 | C38: Statistics Item | D38: Total | F38: North Region | K38: South Region | N38: Market Surveillance | Q38: Border Control | T38: Operations + Admin
C39: Total Orders Issued and Closed | D39: Issued | E39: Closed | G39: Issued - Malta | H39: Issued - Gozo | I39: Closed - Malta | J39: Closed - Gozo | L39: Issued | M39: Closed | O39: Issued | P39: Closed | R39: Issued | S39: Closed | U39: Issued | V39: Closed
D40: =SUM(G40,H40,L40,O40,R40,U40) -> 0 | E40: =SUM(I40,J40,M40,P40,S40,V40) -> 0 | G40: =SUM(G41:G70) -> 0 | H40: =SUM(H41:H70) -> 0 | I40: =SUM(I41:I70) -> 0 | J40: =SUM(J41:J70) -> 0 | L40: =SUM(L41:L70) -> 0 | M40: =SUM(M41:M70) -> 0 | O40: =SUM(O41:O46) -> 0 | P40: =SUM(P41:P46) -> 0 | R40: =SUM(R41:R47) -> 0 | S40: =SUM(S41:S47) -> 0 | U40: =SUM(U41:U49) -> 0 | V40: =SUM(V41:V49) -> 0
F41: Waste Management Facilities | G41: 0 | H41: 0 | I41: 0 | J41: 0 | K41: Waste Management Facilities | L41: 0 | M41: 0 | N41: Local Waste Transfers – Waste Carriers | O41: 0 | P41: 0 | Q41: Wildlife trade / Species Protection & Control border movements | R41: 0 | S41: 0 | T41: Development / Development permit related | U41: 0 | V41: 0
F42: Quarries and related Industries | G42: 0 | H42: 0 | I42: 0 | J42: 0 | K42: Quarries and related Industries | L42: 0 | M42: 0 | N42: Shipments of waste | O42: 0 | P42: 0 | Q42: Wildlife Trade / Species Protection & Control excluding border movements | R42: 0 | S42: 0 | T42: AERs - Annual Environment Reports | U42: 0 | V42: 0
F43: Manufacturing operations | G43: 0 | H43: 0 | I43: 0 | J43: 0 | K43: Manufacturing operations | L43: 0 | M43: 0 | N43: Recycling points | O43: 0 | P43: 0 | Q43: GMOs - Genetically Modified Organisms | R43: 0 | S43: 0 | T43: Litter | U43: 0 | V43: 0
F44: Pharmaceutical industry | G44: 0 | H44: 0 | I44: 0 | J44: 0 | K44: Pharmaceutical industry | L44: 0 | M44: 0 | N44: Extended Producer Responsibility | O44: 0 | P44: 0 | Q44: FLEGT - Forest Law Enforcement, Governance and Trade | R44: 0 | S44: 0 | T44: Development Permit Clearances | U44: 0 | V44: 0
F45: Petrol Stations | G45: 0 | H45: 0 | I45: 0 | J45: 0 | K45: Petrol Stations | L45: 0 | M45: 0 | N45: Consignment notes | O45: 0 | P45: 0 | Q45: EUTR/EUDR - EU Timber Regulations / EU Deforestation Regulation | R45: 0 | S45: 0 | T45: Nature Activity Reports | U45: 0 | V45: 0
F46: VOCs - Volatile Organic Compounds | G46: 0 | H46: 0 | I46: 0 | J46: 0 | K46: VOCs - Volatile Organic Compounds | L46: 0 | M46: 0 | N46: Disposal at Sea | O46: 0 | P46: 0 | Q46: SUPs - Movement and Importation | R46: 0 | S46: 0 | T46: CCTVs | U46: 0 | V46: 0
F47: MCPs - Medium Combustion Plants | G47: 0 | H47: 0 | I47: 0 | J47: 0 | K47: MCPs - Medium Combustion Plants | L47: 0 | M47: 0 | Q47: SUPs - Placing on the Market | R47: 0 | S47: 0 | T47: EP Consultations | U47: 0 | V47: 0
F48: Maintenance Industries | G48: 0 | H48: 0 | I48: 0 | J48: 0 | K48: Maintenance Industries | L48: 0 | M48: 0 | T48: Strategy / Policy Consultations | U48: 0 | V48: 0
F49: Quarry drone surveys | G49: 0 | H49: 0 | I49: 0 | J49: 0 | K49: Quarry drone surveys | L49: 0 | M49: 0 | T49: Smoking Control on Beaches | U49: 0 | V49: 0
F50: Waste Dumping | G50: 0 | H50: 0 | I50: 0 | J50: 0 | K50: Waste Dumping | L50: 0 | M50: 0 | T50: Not ERA Remit | U50: 0 | V50: 0
C51: ADDITIONAL INFORMATION Issued ORDERS should only be limited to reporting year. Closed ORDERS should include all ORDERS closed in reporting year. | F51: Waste Incineration | G51: 0 | H51: 0 | I51: 0 | J51: 0 | K51: Waste Incineration | L51: 0 | M51: 0
...

Sheet Q1 Dashboard
C2: Cases
C3: Case Opened | D3: Case Closed
B4: (INPUT YEAR) | C4: ='Q1'!D4 -> 0 | D4: ='Q1'!E4 -> 0
C8: Total Number of Inspections
B9: (INPUT YEAR) | C9: ='Q1'!D155 -> 0
B13: Warning Letters Issued & Administrative Fines Issued
C14: Warning Letters | D14: Administrative Fines
B15: (INPUT YEAR) | C15: ='Q1'!D247 -> 0 | D15: ='Q1'!D113 -> 0
B18: Compliance Orders Issued
B19: (INPUT YEAR) | C19: ='Q1'!D40 -> 0
C22: Waste Litter
C23: Inspections | D23: Warning Letters Issued | E23: Fines Issued
B24: (INPUT YEAR) | C24: ='Q1'!U160 -> 0 | D24: ='Q1'!U252 -> 0 | E24: ='Q1'!U117 -> 0
C39: North Inspections | D39: South Inspections | E39: Market Surveillance Inspections | F39: Border Control Inspections | G39: Operations + Admin Inspections | H39: On-Call Inspections
B40: Waste Management Facilities | C40: ='Q1'!G158+'Q1'!H158 -> 0 | D40: ='Q1'!L158 -> 0 | E40: 0 | F40: 0 | G40: 0 | H40: ='Q1'!X160+'Q1'!Y160 -> 0
B41: Quarries and related Industries | C41: ='Q1'!G159+'Q1'!H159 -> 0 | D41: ='Q1'!L159 -> 0 | E41: 0 | F41: 0 | G41: 0 | H41: ='Q1'!X161+'Q1'!Y161 -> 0
B42: Manufacturing operations | C42: ='Q1'!G160+'Q1'!H160 -> 0 | D42: ='Q1'!L160 -> 0 | E42: 0 | F42: 0 | G42: 0 | H42: ='Q1'!X162+'Q1'!Y162 -> 0
B43: Pharmaceutical industry | C43: ='Q1'!G161+'Q1'!H161 -> 0 | D43: ='Q1'!L161 -> 0 | E43: 0 | F43: 0 | G43: 0 | H43: ='Q1'!X163+'Q1'!Y163 -> 0
B44: Petrol Stations | C44: ='Q1'!G162+'Q1'!H162 -> 0 | D44: ='Q1'!L162 -> 0 | E44: 0 | F44: 0 | G44: 0 | H44: ='Q1'!X164+'Q1'!Y164 -> 0
B45: VOCs - Volatile Organic Compounds | C45: ='Q1'!G163+'Q1'!H163 -> 0 | D45: ='Q1'!L163 -> 0 | E45: 0 | F45: 0 | G45: 0 | H45: ='Q1'!X165+'Q1'!Y165 -> 0
B46: MCPs - Medium Combustion Plants | C46: ='Q1'!G164+'Q1'!H164 -> 0 | D46: ='Q1'!L164 -> 0 | E46: 0 | F46: 0 | G46: 0 | H46: ='Q1'!X166+'Q1'!Y166 -> 0
B47: Maintenance Industries | C47: ='Q1'!G165+'Q1'!H165 -> 0 | D47: ='Q1'!L165 -> 0 | E47: 0 | F47: 0 | G47: 0 | H47: ='Q1'!X167+'Q1'!Y167 -> 0
B48: Quarry drone surveys | C48: ='Q1'!G166+'Q1'!H166 -> 0 | D48: ='Q1'!L166 -> 0 | E48: 0 | F48: 0 | G48: 0 | H48: ='Q1'!X168+'Q1'!Y168 -> 0
B49: Waste Dumping | C49: ='Q1'!G167+'Q1'!H167 -> 0 | D49: ='Q1'!L167 -> 0 | E49: 0 | F49: 0 | G49: 0 | H49: ='Q1'!X169+'Q1'!Y169 -> 0
B50: Waste Incineration | C50: ='Q1'!G168+'Q1'!H168 -> 0 | D50: ='Q1'!L168 -> 0 | E50: 0 | F50: 0 | G50: 0 | H50: ='Q1'!X170+'Q1'!Y170 -> 0
B51: Farm operations | C51: ='Q1'!G169+'Q1'!H169 -> 0 | D51: ='Q1'!L169 -> 0 | E51: 0 | F51: 0 | G51: 0 | H51: ='Q1'!X171+'Q1'!Y171 -> 0
... B69: Oil Spills / Major Incidents | C69: ='Q1'!G187+'Q1'!H187 -> 0 | D69: ='Q1'!L187 -> 0 | E69: 0 | F69: 0 | G69: 0 | H69: ='Q1'!X189+'Q1'!Y189 -> 0
B70: Local Waste Transfers – Waste Carriers | C70: 0 | D70: 0 | E70: ='Q1'!O158 -> 0 | F70: 0 | G70: 0 | H70: 0
B71: Shipments of waste | C71: 0 | D71: 0 | E71: ='Q1'!O159 -> 0 | F71: 0 | G71: 0 | H71: ='Q1'!X191+'Q1'!Y191 -> 0
B72: Recycling points | C72: 0 | D72: 0 | E72: ='Q1'!O160 -> 0 | F72: 0 | G72: 0 | H72: ='Q1'!X192+'Q1'!Y192 -> 0
B73: Extended Producer Responsibility | C73: 0 | D73: 0 | E73: ='Q1'!O161 -> 0 | F73: 0 | G73: 0 | H73: ='Q1'!X193+'Q1'!Y193 -> 0
B74: Consignment notes | C74: 0 | D74: 0 | E74: ='Q1'!O162 -> 0 | F74: 0 | G74: 0 | H74: ='Q1'!X194+'Q1'!Y194 -> 0
B75: Disposal at Sea | C75: 0 | D75: 0 | E75: ='Q1'!O163 -> 0 | F75: 0 | G75: 0 | H75: ='Q1'!X195+'Q1'!Y195 -> 0
B76: Wildlife trade / Species Protection & Control border movements | C76: 0 | D76: 0 | E76: 0 | F76: ='Q1'!R158 -> 0 | G76: 0 | H76: ='Q1'!X196+'Q1'!Y196 -> 0
B77: Wildlife Trade / Species Protection & Control excluding border movements | C77: 0 | D77: 0 | E77: 0 | F77: ='Q1'!R159 -> 0 | G77: 0 | H77: ='Q1'!X197+'Q1'!Y197 -> 0
B78: GMOs - Genetically Modified Organisms | C78: 0 | D78: 0 | E78: 0 | F78: ='Q1'!R160 -> 0 | G78: 0 | H78: ='Q1'!X198+'Q1'!Y198 -> 0
B79: FLEGT - Forest Law Enforcement, Governance and Trade | C79: 0 | D79: 0 | E79: 0 | F79: ='Q1'!R161 -> 0 | G79: 0 | H79: ='Q1'!X199+'Q1'!Y199 -> 0
B80: EUTR/EUDR - EU Timber Regulations / EU Deforestation Regulation | C80: 0 | D80: 0 | E80: 0 | F80: ='Q1'!R162 -> 0 | G80: 0 | H80: ='Q1'!X200+'Q1'!Y200 -> 0
B81: SUPs - Movement and Importation | C81: 0 | D81: 0 | E81: 0 | F81: ='Q1'!R163 -> 0 | G81: 0 | H81: ='Q1'!X201+'Q1'!Y201 -> 0
B82: SUPs - Placing on the Market | C82: 0 | D82: 0 | E82: 0 | F82: ='Q1'!R164 -> 0 | G82: 0 | H82: ='Q1'!X202+'Q1'!Y202 -> 0
...

Sheet April
B2: 1 | C2: Statistics Item | D2: Total | F2: North Region | K2: South Region | N2: Market Surveillance | Q2: Border Control | T2: Operations + Admin
C3: Total Cases and/or Complaints (Internal & External) received and closed | D3: Opened | E3: Closed | G3: Opened - Malta | H3: Opened - Gozo | I3: Closed - Malta | J3: Closed - Gozo | L3: Opened | M3: Closed | O3: Opened | P3: Closed | R3: Opened | S3: Closed | U3: Opened | V3: Closed
D4: =SUM(G4,H4,L4,O4,R4,U4) -> 0 | E4: =SUM(I4,J4,M4,P4,S4,V4) -> 0 | G4: =SUM(G5:G34) -> 0 | H4: =SUM(H5:H34) -> 0 | I4: =SUM(I5:I34) -> 0 | J4: =SUM(J5:J34) -> 0 | L4: =SUM(L5:L34) -> 0 | M4: =SUM(M5:M34) -> 0 | O4: =SUM(O5:O10) -> 0 | P4: =SUM(P5:P10) -> 0 | R4: =SUM(R5:R11) -> 0 | S4: =SUM(S5:S11) -> 0 | U4: =SUM(U5:U13) -> 0 | V4: =SUM(V5:V13) -> 0
F5: Waste Management Facilities | G5: 0 | H5: 0 | I5: 0 | J5: 0 | K5: Waste Management Facilities | L5: 0 | M5: 0 | N5: Local Waste Transfers – Waste Carriers | O5: 0 | P5: 0 | Q5: Wildlife trade / Species Protection & Control border movements | R5: 0 | S5: 0 | T5: Development / Development permit related | U5: 0 | V5: 0
F6: Quarries and related Industries | G6: 0 | H6: 0 | I6: 0 | J6: 0 | K6: Quarries and related Industries | L6: 0 | M6: 0 | N6: Shipments of waste | O6: 0 | P6: 0 | Q6: Wildlife Trade / Species Protection & Control excluding border movements | R6: 0 | S6: 0 | T6: AERs - Annual Environment Reports | U6: 0 | V6: 0
F7: Manufacturing operations | G7: 0 | H7: 0 | I7: 0 | J7: 0 | K7: Manufacturing operations | L7: 0 | M7: 0 | N7: Recycling points | O7: 0 | P7: 0 | Q7: GMOs - Genetically Modified Organisms | R7: 0 | S7: 0 | T7: Litter | U7: 0 | V7: 0
F8: Pharmaceutical industry | G8: 0 | H8: 0 | I8: 0 | J8: 0 | K8: Pharmaceutical industry | L8: 0 | M8: 0 | N8: Extended Producer Responsibility | O8: 0 | P8: 0 | Q8: FLEGT - Forest Law Enforcement, Governance and Trade | R8: 0 | S8: 0 | T8: Development Permit Clearances | U8: 0 | V8: 0
F9: Petrol Stations | G9: 0 | H9: 0 | I9: 0 | J9: 0 | K9: Petrol Stations | L9: 0 | M9: 0 | N9: Consignment notes | O9: 0 | P9: 0 | Q9: EUTR/EUDR - EU Timber Regulations / EU Deforestation Regulation | R9: 0 | S9: 0 | T9: Nature Activity Reports | U9: 0 | V9: 0
F10: VOCs - Volatile Organic Compounds | G10: 0 | H10: 0 | I10: 0 | J10: 0 | K10: VOCs - Volatile Organic Compounds | L10: 0 | M10: 0 | N10: Disposal at Sea | O10: 0 | P10: 0 | Q10: SUPs - Movement and Importation | R10: 0 | S10: 0 | T10: CCTVs | U10: 0 | V10: 0
F11: MCPs - Medium Combustion Plants | G11: 0 | H11: 0 | I11: 0 | J11: 0 | K11: MCPs - Medium Combustion Plants | L11: 0 | M11: 0 | Q11: SUPs - Placing on the Market | R11: 0 | S11: 0 | T11: EP Consultations | U11: 0 | V11: 0
C12: ADDITIONAL INFORMATION This data will be collected by CED Operations/Admin: - Cases Opened during reporting year - Cases Closed only during reporting year (including cases opened in years prior to the reporting year) | F12: Maintenance Industries | G12: 0 | H12: 0 | I12: 0 | J12: 0 | K12: Maintenance Industries | L12: 0 | M12: 0 | T12: Strategy / Policy Consultations | U12: 0 | V12: 0
F13: Quarry drone surveys | G13: 0 | H13: 0 | I13: 0 | J13: 0 | K13: Quarry drone surveys | L13: 0 | M13: 0 | T13: Smoking Control on Beaches | U13: 0 | V13: 0
F14: Waste Dumping | G14: 0 | H14: 0 | I14: 0 | J14: 0 | K14: Waste Dumping | L14: 0 | M14: 0 | T14: Not ERA Remit | U14: 0 | V14: 0
F15: Waste Incineration | G15: 0 | H15: 0 | I15: 0 | J15: 0 | K15: Waste Incineration | L15: 0 | M15: 0
F16: Farm operations | G16: 0 | H16: 0 | I16: 0 | J16: 0 | K16: Farm operations | L16: 0 | M16: 0
F17: Aquaculture | G17: 0 | H17: 0 | I17: 0 | J17: 0 | K17: Aquaculture | L17: 0 | M17: 0
F18: COMAH - Control of Major Accident Hazards | G18: 0 | H18: 0 | I18: 0 | J18: 0 | K18: COMAH - Control of Major Accident Hazards | L18: 0 | M18: 0
F19: LCPs, STPs, ROs, NFRP and Port Facilities | G19: 0 | H19: 0 | I19: 0 | J19: 0 | K19: LCPs, STPs, ROs, NFRP and Port Facilities | L19: 0 | M19: 0
F20: Fuel Terminals | G20: 0 | H20: 0 | I20: 0 | J20: 0 | K20: Fuel Terminals | L20: 0 | M20: 0
F21: Construction / Demolition -related marine pollution | G21: 0 | H21: 0 | I21: 0 | J21: 0 | K21: Construction / Demolition -related marine pollution | L21: 0 | M21: 0
F22: Hotels and hospitality | G22: 0 | H22: 0 | I22: 0 | J22: 0 | K22: Hotels and hospitality | L22: 0 | M22: 0
F23: Groundwater (Boreholes) | G23: 0 | H23: 0 | I23: 0 | J23: 0 | K23: Groundwater (Boreholes) | L23: 0 | M23: 0
F24: Sewage in sea | G24: 0 | H24: 0 | I24: 0 | J24: 0 | K24: Sewage in sea | L24: 0 | M24: 0
F25: Exceedances in emissions/discharges | G25: 0 | H25: 0 | I25: 0 | J25: 0 | K25: Exceedances in emissions/discharges | L25: 0 | M25: 0
F26: Tree Protection | G26: 0 | H26: 0 | I26: 0 | J26: 0 | K26: Tree Protection | L26: 0 | M26: 0
... F34: Oil Spills / Major Incidents | G34: 0 | H34: 0 | I34: 0 | J34: 0 | K34: Oil Spills / Major Incidents | L34: 0 | M34: 0
B38: 2 | C38: Statistics Item | D38: Total | F38: North Region | K38: South Region | N38: Market Surveillance | Q38: Border Control | T38: Operations + Admin
C39: Total Orders Issued and Closed | D39: Issued | E39: Closed | G39: Issued - Malta | H39: Issued - Gozo | I39: Closed - Malta | J39: Closed - Gozo | L39: Issued | M39: Closed | O39: Issued | P39: Closed | R39: Issued | S39: Closed | U39: Issued | V39: Closed
D40: =SUM(G40,H40,L40,O40,R40,U40) -> 0 | E40: =SUM(I40,J40,M40,P40,S40,V40) -> 0 | G40: =SUM(G41:G70) -> 0 | H40: =SUM(H41:H70) -> 0 | I40: =SUM(I41:I70) -> 0 | J40: =SUM(J41:J70) -> 0 | L40: =SUM(L41:L70) -> 0 | M40: =SUM(M41:M70) -> 0 | O40: =SUM(O41:O46) -> 0 | P40: =SUM(P41:P46) -> 0 | R40: =SUM(R41:R47) -> 0 | S40: =SUM(S41:S47) -> 0 | U40: =SUM(U41:U49) -> 0 | V40: =SUM(V41:V49) -> 0
F41: Waste Management Facilities | G41: 0 | H41: 0 | I41: 0 | J41: 0 | K41: Waste Management Facilities | L41: 0 | M41: 0 | N41: Local Waste Transfers – Waste Carriers | O41: 0 | P41: 0 | Q41: Wildlife trade / Species Protection & Control border movements | R41: 0 | S41: 0 | T41: Development / Development permit related | U41: 0 | V41: 0
F42: Quarries and related Industries | G42: 0 | H42: 0 | I42: 0 | J42: 0 | K42: Quarries and related Industries | L42: 0 | M42: 0 | N42: Shipments of waste | O42: 0 | P42: 0 | Q42: Wildlife Trade / Species Protection & Control excluding border movements | R42: 0 | S42: 0 | T42: AERs - Annual Environment Reports | U42: 0 | V42: 0
F43: Manufacturing operations | G43: 0 | H43: 0 | I43: 0 | J43: 0 | K43: Manufacturing operations | L43: 0 | M43: 0 | N43: Recycling points | O43: 0 | P43: 0 | Q43: GMOs - Genetically Modified Organisms | R43: 0 | S43: 0 | T43: Litter | U43: 0 | V43: 0
F44: Pharmaceutical industry | G44: 0 | H44: 0 | I44: 0 | J44: 0 | K44: Pharmaceutical industry | L44: 0 | M44: 0 | N44: Extended Producer Responsibility | O44: 0 | P44: 0 | Q44: FLEGT - Forest Law Enforcement, Governance and Trade | R44: 0 | S44: 0 | T44: Development Permit Clearances | U44: 0 | V44: 0
F45: Petrol Stations | G45: 0 | H45: 0 | I45: 0 | J45: 0 | K45: Petrol Stations | L45: 0 | M45: 0 | N45: Consignment notes | O45: 0 | P45: 0 | Q45: EUTR/EUDR - EU Timber Regulations / EU Deforestation Regulation | R45: 0 | S45: 0 | T45: Nature Activity Reports | U45: 0 | V45: 0
F46: VOCs - Volatile Organic Compounds | G46: 0 | H46: 0 | I46: 0 | J46: 0 | K46: VOCs - Volatile Organic Compounds | L46: 0 | M46: 0 | N46: Disposal at Sea | O46: 0 | P46: 0 | Q46: SUPs - Movement and Importation | R46: 0 | S46: 0 | T46: CCTVs | U46: 0 | V46: 0
F47: MCPs - Medium Combustion Plants | G47: 0 | H47: 0 | I47: 0 | J47: 0 | K47: MCPs - Medium Combustion Plants | L47: 0 | M47: 0 | Q47: SUPs - Placing on the Market | R47: 0 | S47: 0 | T47: EP Consultations | U47: 0 | V47: 0
F48: Maintenance Industries | G48: 0 | H48: 0 | I48: 0 | J48: 0 | K48: Maintenance Industries | L48: 0 | M48: 0 | T48: Strategy / Policy Consultations | U48: 0 | V48: 0
F49: Quarry drone surveys | G49: 0 | H49: 0 | I49: 0 | J49: 0 | K49: Quarry drone surveys | L49: 0 | M49: 0 | T49: Smoking Control on Beaches | U49: 0 | V49: 0
F50: Waste Dumping | G50: 0 | H50: 0 | I50: 0 | J50: 0 | K50: Waste Dumping | L50: 0 | M50: 0 | T50: Not ERA Remit | U50: 0 | V50: 0
C51: ADDITIONAL INFORMATION Issued ORDERS should only be limited to reporting year. Closed ORDERS should include all ORDERS closed in reporting year. | F51: Waste Incineration | G51: 0 | H51: 0 | I51: 0 | J51: 0 | K51: Waste Incineration | L51: 0 | M51: 0
...

Sheet May
B2: 1 | C2: Statistics Item | D2: Total | F2: North Region | K2: South Region | N2: Market Surveillance | Q2: Border Control | T2: Operations + Admin
C3: Total Cases and/or Complaints (Internal & External) received and closed | D3: Opened | E3: Closed | G3: Opened - Malta | H3: Opened - Gozo | I3: Closed - Malta | J3: Closed - Gozo | L3: Opened | M3: Closed | O3: Opened | P3: Closed | R3: Opened | S3: Closed | U3: Opened | V3: Closed
D4: =SUM(G4,H4,L4,O4,R4,U4) -> 0 | E4: =SUM(I4,J4,M4,P4,S4,V4) -> 0 | G4: =SUM(G5:G34) -> 0 | H4: =SUM(H5:H34) -> 0 | I4: =SUM(I5:I34) -> 0 | J4: =SUM(J5:J34) -> 0 | L4: =SUM(L5:L34) -> 0 | M4: =SUM(M5:M34) -> 0 | O4: =SUM(O5:O10) -> 0 | P4: =SUM(P5:P10) -> 0 | R4: =SUM(R5:R11) -> 0 | S4: =SUM(S5:S11) -> 0 | U4: =SUM(U5:U13) -> 0 | V4: =SUM(V5:V13) -> 0
F5: Waste Management Facilities | G5: 0 | H5: 0 | I5: 0 | J5: 0 | K5: Waste Management Facilities | L5: 0 | M5: 0 | N5: Local Waste Transfers – Waste Carriers | O5: 0 | P5: 0 | Q5: Wildlife trade / Species Protection & Control border movements | R5: 0 | S5: 0 | T5: Development / Development permit related | U5: 0 | V5: 0
F6: Quarries and related Industries | G6: 0 | H6: 0 | I6: 0 | J6: 0 | K6: Quarries and related Industries | L6: 0 | M6: 0 | N6: Shipments of waste | O6: 0 | P6: 0 | Q6: Wildlife Trade / Species Protection & Control excluding border movements | R6: 0 | S6: 0 | T6: AERs - Annual Environment Reports | U6: 0 | V6: 0
F7: Manufacturing operations | G7: 0 | H7: 0 | I7: 0 | J7: 0 | K7: Manufacturing operations | L7: 0 | M7: 0 | N7: Recycling points | O7: 0 | P7: 0 | Q7: GMOs - Genetically Modified Organisms | R7: 0 | S7: 0 | T7: Litter | U7: 0 | V7: 0
F8: Pharmaceutical industry | G8: 0 | H8: 0 | I8: 0 | J8: 0 | K8: Pharmaceutical industry | L8: 0 | M8: 0 | N8: Extended Producer Responsibility | O8: 0 | P8: 0 | Q8: FLEGT - Forest Law Enforcement, Governance and Trade | R8: 0 | S8: 0 | T8: Development Permit Clearances | U8: 0 | V8: 0
F9: Petrol Stations | G9: 0 | H9: 0 | I9: 0 | J9: 0 | K9: Petrol Stations | L9: 0 | M9: 0 | N9: Consignment notes | O9: 0 | P9: 0 | Q9: EUTR/EUDR - EU Timber Regulations / EU Deforestation Regulation | R9: 0 | S9: 0 | T9: Nature Activity Reports | U9: 0 | V9: 0
F10: VOCs - Volatile Organic Compounds | G10: 0 | H10: 0 | I10: 0 | J10: 0 | K10: VOCs - Volatile Organic Compounds | L10: 0 | M10: 0 | N10: Disposal at Sea | O10: 0 | P10: 0 | Q10: SUPs - Movement and Importation | R10: 0 | S10: 0 | T10: CCTVs | U10: 0 | V10: 0
F11: MCPs - Medium Combustion Plants | G11: 0 | H11: 0 | I11: 0 | J11: 0 | K11: MCPs - Medium Combustion Plants | L11: 0 | M11: 0 | Q11: SUPs - Placing on the Market | R11: 0 | S11: 0 | T11: EP Consultations | U11: 0 | V11: 0
C12: ADDITIONAL INFORMATION This data will be collected by CED Operations/Admin: - Cases Opened during reporting year - Cases Closed only during reporting year (including cases opened in years prior to the reporting year) | F12: Maintenance Industries | G12: 0 | H12: 0 | I12: 0 | J12: 0 | K12: Maintenance Industries | L12: 0 | M12: 0 | T12: Strategy / Policy Consultations | U12: 0 | V12: 0
F13: Quarry drone surveys | G13: 0 | H13: 0 | I13: 0 | J13: 0 | K13: Quarry drone surveys | L13: 0 | M13: 0 | T13: Smoking Control on Beaches | U13: 0 | V13: 0
F14: Waste Dumping | G14: 0 | H14: 0 | I14: 0 | J14: 0 | K14: Waste Dumping | L14: 0 | M14: 0 | T14: Not ERA Remit | U14: 0 | V14: 0
F15: Waste Incineration | G15: 0 | H15: 0 | I15: 0 | J15: 0 | K15: Waste Incineration | L15: 0 | M15: 0
F16: Farm operations | G16: 0 | H16: 0 | I16: 0 | J16: 0 | K16: Farm operations | L16: 0 | M16: 0
F17: Aquaculture | G17: 0 | H17: 0 | I17: 0 | J17: 0 | K17: Aquaculture | L17: 0 | M17: 0
F18: COMAH - Control of Major Accident Hazards | G18: 0 | H18: 0 | I18: 0 | J18: 0 | K18: COMAH - Control of Major Accident Hazards | L18: 0 | M18: 0
F19: LCPs, STPs, ROs, NFRP and Port Facilities | G19: 0 | H19: 0 | I19: 0 | J19: 0 | K19: LCPs, STPs, ROs, NFRP and Port Facilities | L19: 0 | M19: 0
F20: Fuel Terminals | G20: 0 | H20: 0 | I20: 0 | J20: 0 | K20: Fuel Terminals | L20: 0 | M20: 0
F21: Construction / Demolition -related marine pollution | G21: 0 | H21: 0 | I21: 0 | J21: 0 | K21: Construction / Demolition -related marine pollution | L21: 0 | M21: 0
F22: Hotels and hospitality | G22: 0 | H22: 0 | I22: 0 | J22: 0 | K22: Hotels and hospitality | L22: 0 | M22: 0
F23: Groundwater (Boreholes) | G23: 0 | H23: 0 | I23: 0 | J23: 0 | K23: Groundwater (Boreholes) | L23: 0 | M23: 0
F24: Sewage in sea | G24: 0 | H24: 0 | I24: 0 | J24: 0 | K24: Sewage in sea | L24: 0 | M24: 0
F25: Exceedances in emissions/discharges | G25: 0 | H25: 0 | I25: 0 | J25: 0 | K25: Exceedances in emissions/discharges | L25: 0 | M25: 0
F26: Tree Protection | G26: 0 | H26: 0 | I26: 0 | J26: 0 | K26: Tree Protection | L26: 0 | M26: 0
... F34: Oil Spills / Major Incidents | G34: 0 | H34: 0 | I34: 0 | J34: 0 | K34: Oil Spills / Major Incidents | L34: 0 | M34: 0
B38: 2 | C38: Statistics Item | D38: Total | F38: North Region | K38: South Region | N38: Market Surveillance | Q38: Border Control | T38: Operations + Admin
C39: Total Orders Issued and Closed | D39: Issued | E39: Closed | G39: Issued - Malta | H39: Issued - Gozo | I39: Closed - Malta | J39: Closed - Gozo | L39: Issued | M39: Closed | O39: Issued | P39: Closed | R39: Issued | S39: Closed | U39: Issued | V39: Closed
D40: =SUM(G40,H40,L40,O40,R40,U40) -> 0 | E40: =SUM(I40,J40,M40,P40,S40,V40) -> 0 | G40: =SUM(G41:G70) -> 0 | H40: =SUM(H41:H70) -> 0 | I40: =SUM(I41:I70) -> 0 | J40: =SUM(J41:J70) -> 0 | L40: =SUM(L41:L70) -> 0 | M40: =SUM(M41:M70) -> 0 | O40: =SUM(O41:O46) -> 0 | P40: =SUM(P41:P46) -> 0 | R40: =SUM(R41:R47) -> 0 | S40: =SUM(S41:S47) -> 0 | U40: =SUM(U41:U49) -> 0 | V40: =SUM(V41:V49) -> 0
F41: Waste Management Facilities | G41: 0 | H41: 0 | I41: 0 | J41: 0 | K41: Waste Management Facilities | L41: 0 | M41: 0 | N41: Local Waste Transfers – Waste Carriers | O41: 0 | P41: 0 | Q41: Wildlife trade / Species Protection & Control border movements | R41: 0 | S41: 0 | T41: Development / Development permit related | U41: 0 | V41: 0
F42: Quarries and related Industries | G42: 0 | H42: 0 | I42: 0 | J42: 0 | K42: Quarries and related Industries | L42: 0 | M42: 0 | N42: Shipments of waste | O42: 0 | P42: 0 | Q42: Wildlife Trade / Species Protection & Control excluding border movements | R42: 0 | S42: 0 | T42: AERs - Annual Environment Reports | U42: 0 | V42: 0
F43: Manufacturing operations | G43: 0 | H43: 0 | I43: 0 | J43: 0 | K43: Manufacturing operations | L43: 0 | M43: 0 | N43: Recycling points | O43: 0 | P43: 0 | Q43: GMOs - Genetically Modified Organisms | R43: 0 | S43: 0 | T43: Litter | U43: 0 | V43: 0
F44: Pharmaceutical industry | G44: 0 | H44: 0 | I44: 0 | J44: 0 | K44: Pharmaceutical industry | L44: 0 | M44: 0 | N44: Extended Producer Responsibility | O44: 0 | P44: 0 | Q44: FLEGT - Forest Law Enforcement, Governance and Trade | R44: 0 | S44: 0 | T44: Development Permit Clearances | U44: 0 | V44: 0
F45: Petrol Stations | G45: 0 | H45: 0 | I45: 0 | J45: 0 | K45: Petrol Stations | L45: 0 | M45: 0 | N45: Consignment notes | O45: 0 | P45: 0 | Q45: EUTR/EUDR - EU Timber Regulations / EU Deforestation Regulation | R45: 0 | S45: 0 | T45: Nature Activity Reports | U45: 0 | V45: 0
F46: VOCs - Volatile Organic Compounds | G46: 0 | H46: 0 | I46: 0 | J46: 0 | K46: VOCs - Volatile Organic Compounds | L46: 0 | M46: 0 | N46: Disposal at Sea | O46: 0 | P46: 0 | Q46: SUPs - Movement and Importation | R46: 0 | S46: 0 | T46: CCTVs | U46: 0 | V46: 0
F47: MCPs - Medium Combustion Plants | G47: 0 | H47: 0 | I47: 0 | J47: 0 | K47: MCPs - Medium Combustion Plants | L47: 0 | M47: 0 | Q47: SUPs - Placing on the Market | R47: 0 | S47: 0 | T47: EP Consultations | U47: 0 | V47: 0
F48: Maintenance Industries | G48: 0 | H48: 0 | I48: 0 | J48: 0 | K48: Maintenance Industries | L48: 0 | M48: 0 | T48: Strategy / Policy Consultations | U48: 0 | V48: 0
F49: Quarry drone surveys | G49: 0 | H49: 0 | I49: 0 | J49: 0 | K49: Quarry drone surveys | L49: 0 | M49: 0 | T49: Smoking Control on Beaches | U49: 0 | V49: 0
F50: Waste Dumping | G50: 0 | H50: 0 | I50: 0 | J50: 0 | K50: Waste Dumping | L50: 0 | M50: 0 | T50: Not ERA Remit | U50: 0 | V50: 0
C51: ADDITIONAL INFORMATION Issued ORDERS should only be limited to reporting year. Closed ORDERS should include all ORDERS closed in reporting year. | F51: Waste Incineration | G51: 0 | H51: 0 | I51: 0 | J51: 0 | K51: Waste Incineration | L51: 0 | M51: 0
...

Sheet June
B2: 1 | C2: Statistics Item | D2: Total | F2: North Region | K2: South Region | N2: Market Surveillance | Q2: Border Control | T2: Operations + Admin
C3: Total Cases and/or Complaints (Internal & External) received and closed | D3: Opened | E3: Closed | G3: Opened - Malta | H3: Opened - Gozo | I3: Closed - Malta | J3: Closed - Gozo | L3: Opened | M3: Closed | O3: Opened | P3: Closed | R3: Opened | S3: Closed | U3: Opened | V3: Closed
D4: =SUM(G4,H4,L4,O4,R4,U4) -> 0 | E4: =SUM(I4,J4,M4,P4,S4,V4) -> 0 | G4: =SUM(G5:G34) -> 0 | H4: =SUM(H5:H34) -> 0 | I4: =SUM(I5:I34) -> 0 | J4: =SUM(J5:J34) -> 0 | L4: =SUM(L5:L34) -> 0 | M4: =SUM(M5:M34) -> 0 | O4: =SUM(O5:O10) -> 0 | P4: =SUM(P5:P10) -> 0 | R4: =SUM(R5:R11) -> 0 | S4: =SUM(S5:S11) -> 0 | U4: =SUM(U5:U13) -> 0 | V4: =SUM(V5:V13) -> 0
F5: Waste Management Facilities | G5: 0 | H5: 0 | I5: 0 | J5: 0 | K5: Waste Management Facilities | L5: 0 | M5: 0 | N5: Local Waste Transfers – Waste Carriers | O5: 0 | P5: 0 | Q5: Wildlife trade / Species Protection & Control border movements | R5: 0 | S5: 0 | T5: Development / Development permit related | U5: 0 | V5: 0
F6: Quarries and related Industries | G6: 0 | H6: 0 | I6: 0 | J6: 0 | K6: Quarries and related Industries | L6: 0 | M6: 0 | N6: Shipments of waste | O6: 0 | P6: 0 | Q6: Wildlife Trade / Species Protection & Control excluding border movements | R6: 0 | S6: 0 | T6: AERs - Annual Environment Reports | U6: 0 | V6: 0
F7: Manufacturing operations | G7: 0 | H7: 0 | I7: 0 | J7: 0 | K7: Manufacturing operations | L7: 0 | M7: 0 | N7: Recycling points | O7: 0 | P7: 0 | Q7: GMOs - Genetically Modified Organisms | R7: 0 | S7: 0 | T7: Litter | U7: 0 | V7: 0
F8: Pharmaceutical industry | G8: 0 | H8: 0 | I8: 0 | J8: 0 | K8: Pharmaceutical industry | L8: 0 | M8: 0 | N8: Extended Producer Responsibility | O8: 0 | P8: 0 | Q8: FLEGT - Forest Law Enforcement, Governance and Trade | R8: 0 | S8: 0 | T8: Development Permit Clearances | U8: 0 | V8: 0
F9: Petrol Stations | G9: 0 | H9: 0 | I9: 0 | J9: 0 | K9: Petrol Stations | L9: 0 | M9: 0 | N9: Consignment notes | O9: 0 | P9: 0 | Q9: EUTR/EUDR - EU Timber Regulations / EU Deforestation Regulation | R9: 0 | S9: 0 | T9: Nature Activity Reports | U9: 0 | V9: 0
F10: VOCs - Volatile Organic Compounds | G10: 0 | H10: 0 | I10: 0 | J10: 0 | K10: VOCs - Volatile Organic Compounds | L10: 0 | M10: 0 | N10: Disposal at Sea | O10: 0 | P10: 0 | Q10: SUPs - Movement and Importation | R10: 0 | S10: 0 | T10: CCTVs | U10: 0 | V10: 0
F11: MCPs - Medium Combustion Plants | G11: 0 | H11: 0 | I11: 0 | J11: 0 | K11: MCPs - Medium Combustion Plants | L11: 0 | M11: 0 | Q11: SUPs - Placing on the Market | R11: 0 | S11: 0 | T11: EP Consultations | U11: 0 | V11: 0
C12: ADDITIONAL INFORMATION This data will be collected by CED Operations/Admin: - Cases Opened during reporting year - Cases Closed only during reporting year (including cases opened in years prior to the reporting year) | F12: Maintenance Industries | G12: 0 | H12: 0 | I12: 0 | J12: 0 | K12: Maintenance Industries | L12: 0 | M12: 0 | T12: Strategy / Policy Consultations | U12: 0 | V12: 0
F13: Quarry drone surveys | G13: 0 | H13: 0 | I13: 0 | J13: 0 | K13: Quarry drone surveys | L13: 0 | M13: 0 | T13: Smoking Control on Beaches | U13: 0 | V13: 0
F14: Waste Dumping | G14: 0 | H14: 0 | I14: 0 | J14: 0 | K14: Waste Dumping | L14: 0 | M14: 0 | T14: Not ERA Remit | U14: 0 | V14: 0
F15: Waste Incineration | G15: 0 | H15: 0 | I15: 0 | J15: 0 | K15: Waste Incineration | L15: 0 | M15: 0
F16: Farm operations | G16: 0 | H16: 0 | I16: 0 | J16: 0 | K16: Farm operations | L16: 0 | M16: 0
F17: Aquaculture | G17: 0 | H17: 0 | I17: 0 | J17: 0 | K17: Aquaculture | L17: 0 | M17: 0
F18: COMAH - Control of Major Accident Hazards | G18: 0 | H18: 0 | I18: 0 | J18: 0 | K18: COMAH - Control of Major Accident Hazards | L18: 0 | M18: 0
F19: LCPs, STPs, ROs, NFRP and Port Facilities | G19: 0 | H19: 0 | I19: 0 | J19: 0 | K19: LCPs, STPs, ROs, NFRP and Port Facilities | L19: 0 | M19: 0
F20: Fuel Terminals | G20: 0 | H20: 0 | I20: 0 | J20: 0 | K20: Fuel Terminals | L20: 0 | M20: 0
F21: Construction / Demolition -related marine pollution | G21: 0 | H21: 0 | I21: 0 | J21: 0 | K21: Construction / Demolition -related marine pollution | L21: 0 | M21: 0
F22: Hotels and hospitality | G22: 0 | H22: 0 | I22: 0 | J22: 0 | K22: Hotels and hospitality | L22: 0 | M22: 0
F23: Groundwater (Boreholes) | G23: 0 | H23: 0 | I23: 0 | J23: 0 | K23: Groundwater (Boreholes) | L23: 0 | M23: 0
F24: Sewage in sea | G24: 0 | H24: 0 | I24: 0 | J24: 0 | K24: Sewage in sea | L24: 0 | M24: 0
